{
    "description": "Test that global signOut error returns partial success with global sign out error",
    "preConditions": {
        "amplify-configuration": "authconfiguration.json",
        "state": "SignedIn_SessionEstablished.json",
        "mockedResponses": [
            {
                "type": "cognitoIdentityProvider",
                "apiName": "globalSignOut",
                "responseType": "failure",
                "response": {
                    "errorType": "NotAuthorizedException",
                    "errorMessage": null
                }
            }
        ]
    },
    "api": {
        "name": "signOut",
        "params": {
        },
        "options": {
            "globalSignOut": true
        }
    },
    "validations": [
        {
            "type": "amplify",
            "apiName": "signOut",
            "responseType": "complete",
            "response": {
                "hostedUIError": null,
                "globalSignOutError": {
                    "accessToken": {
                        "isString": true,
                        "content": "eyJhbGciOiJIUzI1NiIsInR5cCI6IkpXVCJ9.eyJzdWIiOiJ1c2VySWQiLCJ1c2VybmFtZSI6InVzZXJuYW1lIiwiZXhwIjoxNTE2MjM5MDIyLCJvcmlnaW5fanRpIjoib3JpZ2luX2p0aSJ9.Xqa-vjJe5wwwsqeRAdHf8kTBn_rYSkDn2lB7xj9Z1xU"
                    },
                    "error": {
                        "errorType": {
                            "isString": true,
                            "content": "GlobalSignOutException"
                        },
                        "errorMessage": {
                            "isString": true,
                            "content": "Failed to sign out globally"
                        },
                        "recoverySuggestion": {
                            "isString": true,
                            "content": "See attached exception for more details. GlobalSignOut can be retried using the CognitoIdentityProviderClient accessible from the escape hatch."
                        },
                        "cause": {
                            "errorType": {
                                "isString": true,
                                "content": "NotAuthorizedException"
                            },
                            "errorMessage": {
                            }
                        }
                    }
                },
                "revokeTokenError": {
                    "refreshToken": {
                        "isString": true,
                        "content": "eyJhbGciOiJIUzI1NiIsInR5cCI6IkpXVCJ9.eyJzdWIiOiJ1c2VySWQiLCJ1c2VybmFtZSI6InVzZXJuYW1lIiwiZXhwIjoxNTE2MjM5MDIyLCJvcmlnaW5fanRpIjoib3JpZ2luX2p0aSJ9.Xqa-vjJe5wwwsqeRAdHf8kTBn_rYSkDn2lB7xj9Z1xU"
                    },
                    "error": {
                        "errorType": {
                            "isString": true,
                            "content": "RevokeTokenException"
                        },
                        "errorMessage": {
                            "isString": true,
                            "content": "Failed to revoke token"
                        },
                        "recoverySuggestion": {
                            "isString": true,
                            "content": "See attached exception for more details. RevokeToken can be retried using the CognitoIdentityProviderClient accessible from the escape hatch."
                        },
                        "cause": {
                            "detailMessage": {
                                "isString": true,
                                "content": "RevokeToken not attempted because GlobalSignOut failed."
                            },
                            "stackTrace": [
                            ],
                            "suppressedExceptions": [
                            ]
                        }
                    }
                }
            }
        }
    ]
}