{
    "description": "Test that global signOut error returns partial success with global sign out error",
    "preConditions": {
        "amplify-configuration": "authconfiguration.json",
        "state": "SignedIn_SessionEstablished.json",
        "mockedResponses": [
            {
                "type": "cognitoIdentityProvider",
                "apiName": "globalSignOut",
                "responseType": "failure",
                "response": {
                    "errorType": "NotAuthorizedException",
                    "errorMessage": "Error type: Client, Protocol response: (empty response)"
                }
            }
        ]
    },
    "api": {
        "name": "signOut",
        "params": {},
        "options": {
            "globalSignOut": true
        }
    },
    "validations": [
        {
            "type": "amplify",
            "apiName": "signOut",
            "responseType": "complete",
            "response": {
                "globalSignOutError": {
                    "accessToken": "eyJhbGciOiJIUzI1NiIsInR5cCI6IkpXVCJ9.eyJzdWIiOiJ1c2VySWQiLCJ1c2VybmFtZSI6InVzZXJuYW1lIiwiZXhwIjoxNTE2MjM5MDIyLCJvcmlnaW5fanRpIjoib3JpZ2luX2p0aSJ9.Xqa-vjJe5wwwsqeRAdHf8kTBn_rYSkDn2lB7xj9Z1xU",
                    "exception": {
                        "errorType": "GlobalSignOutException",
                        "errorMessage": "Failed to sign out globally",
                        "recoverySuggestion": "See attached exception for more details. GlobalSignOut can be retried using the CognitoIdentityProviderClient accessible from the escape hatch.",
                        "cause": {
                            "errorType": "NotAuthorizedException",
                            "errorMessage": "Error type: Client, Protocol response: (empty response)"
                        }
                    }
                },
                "hostedUIError": null,
                "revokeTokenError": {
                    "exception": {
                        "errorType": "RevokeTokenException",
                        "errorMessage": "Failed to revoke token",
                        "recoverySuggestion": "See attached exception for more details. RevokeToken can be retried using the CognitoIdentityProviderClient accessible from the escape hatch.",
                        "cause": {}
                    },
                    "refreshToken": "eyJhbGciOiJIUzI1NiIsInR5cCI6IkpXVCJ9.eyJzdWIiOiJ1c2VySWQiLCJ1c2VybmFtZSI6InVzZXJuYW1lIiwiZXhwIjoxNTE2MjM5MDIyLCJvcmlnaW5fanRpIjoib3JpZ2luX2p0aSJ9.Xqa-vjJe5wwwsqeRAdHf8kTBn_rYSkDn2lB7xj9Z1xU"
                },
                "signedOutLocally": true
            }
        }
    ]
}